Workbook

Sheet 0. Note d utilisation
A1: YELLITAARÉ THIDÉ — OUTIL DE PROCÉDURES FINANCIÈRES
A2: Note d'utilisation — Guide complet de l'outil
B4: Cet outil opérationnalise les Articles 47, 47 bis, 48, 49, 50 et 52 des Statuts de Yellitaaré Thidé. Il comprend 5 feuilles de travail décrites ci-dessous.
A6: 1. DESCRIPTION DES ONGLETS
B7: 📄 1. Seuils & Autorisations — Tableau de référence statutaire
B8: Consultez cet onglet pour connaître immédiatement le niveau d'autorisation requis selon le montant d'une dépense. Contient aussi les plafonds anti-fractionnement (Art. 47 bis) et les modes de paiement autorisés. | G8: Lecture seule — référence
B10: 📄 2. Bon de Dépense — Formulaire de demande de dépense
B11: Remplissez un bon par dépense. Saisissez le montant : le niveau d'autorisation requis s'affiche automatiquement en couleur. Imprimez le bon, faites-le signer, archivez-le avec le justificatif. | G11: Un bon par dépense
B13: 📄 3. Registre Dépenses — Journal chronologique des dépenses
B14: Saisissez chaque dépense validée. Le tableau surveille les plafonds cumulés en temps réel et déclenche des alertes colorées (🟢 OK / 🟠 80% / 🔴 DÉPASSÉ). Les menus déroulants guident la saisie. | G14: Mise à jour après chaque paiement
B16: 📄 4. Registre Cotisations — Suivi nominatif des cotisations
B17: Enregistrez chaque versement de cotisation avec le numéro de reçu. Le statut (✓ À jour / ⚠ Partiel / ✗ Impayé) se colore automatiquement. Le taux de recouvrement par section est calculé en temps réel. | G17: Mise à jour à chaque versement
B19: 📄 5. Tableau de Bord — Vue synthétique et alertes
B20: Synthèse automatique : total cotisations, total dépenses, solde disponible, alertes de plafonds actives. Aucune saisie requise — toutes les données proviennent des onglets 3 et 4. | G20: Consultation uniquement
A23: 2. FLUX DE TRAVAIL — COMMENT TRAITER UNE DÉPENSE
B24: ① Vérifier le seuil
B25: Consulter l'onglet « 1. Seuils & Autorisations » — identifier le niveau requis selon le montant unitaire ET les plafonds cumulés déjà atteints.
B26: ② Remplir le Bon de Dépense
B27: Ouvrir l'onglet « 2. Bon de Dépense » — saisir le montant, l'objet, le bénéficiaire. Le niveau d'autorisation s'affiche automatiquement.
B28: ③ Obtenir les signatures
B29: Imprimer ou faire circuler le bon — collecter les signatures obligatoires selon le niveau : Trésorier seul / + Président CG / + Visa COSC / Vote AG.
B30: ④ Effectuer le paiement
B31: Procéder au paiement par le mode autorisé (virement, chèque, mobile money). Espèces uniquement si ≤ 5 000 MRU avec reçu signé bénéficiaire.
B32: ⑤ Enregistrer dans le Registre
B33: Saisir la dépense dans l'onglet « 3. Registre Dépenses » avec le numéro de bon et la pièce justificative. Vérifier que les plafonds cumulés ne déclenchent pas d'alerte.
B34: ⑥ Signaler si alerte 80 %
B35: Si le cumul mensuel/trimestriel/semestriel atteint 80 % du plafond applicable : signaler immédiatement au Président CG et au COSC (Art. 47 bis §5).
A37: 3. RÈGLES CRITIQUES À NE JAMAIS OUBLIER
B38: 🚫 Zéro compte personnel | C38: Aucun fonds de l'organisation ne transite par un compte personnel, quelle que soit la situation (Art. 46).
B39: 🚫 Zéro fractionnement | C39: Diviser une dépense en plusieurs petites opérations pour contourner un seuil est formellement interdit et constitue une faute grave (Art. 47 bis §4).
B40: 🚫 Zéro paiement sans bon | C40: Tout paiement doit être précédé d'un bon de commande validé par les signataires requis (Art. 48).
B41: ⚠ Alerte obligatoire à 80 % | C41: Le Trésorier est tenu de signaler au Président CG et au COSC dès que le cumul atteint 80 % du plafond — sans attendre le dépassement.
B42: ⚠ Dépassement = faute grave | C42: Tout dépassement de plafond non autorisé préalablement déclenche automatiquement la procédure disciplinaire de l'Art. 60.
B43: ✅ Reçu numéroté systématique | C43: Chaque cotisant reçoit obligatoirement un reçu numéroté. Le registre nominatif est mis à jour à chaque versement (Art. 50).
B44: ✅ Transparence COSC | C44: Le COSC peut vérifier la caisse, consulter les registres et demander un audit externe à tout moment et à la majorité des 2/3 (Art. 49, 53).
A46: 4. RÉFÉRENCES STATUTAIRES
B47: Article | C47: Objet
B48: Art. 46 | C48: Compte bancaire unique — interdiction des comptes personnels
B49: Art. 47 | C49: Seuils d'autorisation des dépenses par opération
B50: Art. 47 bis | C50: Plafonds cumulés — lutte contre le fractionnement
...

Sheet 1. Seuils & Autorisations
A1: YELLITAARÉ THIDÉ — PROCÉDURES FINANCIÈRES
A2: Guide opérationnel — Seuils d'autorisation des dépenses | Art. 47 & 47 bis
A4: A. SEUILS D'AUTORISATION PAR OPÉRATION (Art. 47)
A5: Montant unitaire | B5: Plafond cumulé | C5: Période | D5: Autorisation requise | E5: Signataires obligatoires | F5: Visa COSC | G5: Réf. Statuts
A6: ≤ 5 000 MRU | B6: 20 000 MRU | C6: / Trimestre | D6: Décision du Trésorier seul | E6: Trésorier + Président | F6: Non requis | G6: Art. 47
A7: 5 001 – 50 000 MRU | B7: 100 000 MRU | C7: / Trimestre | D7: Accord du Président du CG | E7: Trésorier + Président + Visa COSC | F7: Obligatoire | G7: Art. 47
A8: 50 001–200 000 MRU | B8: 200 000 MRU | C8: / Semestre | D8: Décision du CG en réunion | E8: Trésorier + Président + Visa COSC | F8: Obligatoire | G8: Art. 47
A9: > 200 000 MRU | B9: Sans plafond | C9: — | D9: Approbation de l'AG (vote requis) | E9: Trésorier + Président + Visa COSC | F9: Obligatoire | G9: Art. 47
A11: B. PLAFONDS CUMULÉS — LUTTE CONTRE LE FRACTIONNEMENT (Art. 47 bis)
A12: Acteur | B12: Plafond | C12: Période | D12: Déclencheur d'alerte (80%) | E12: Conséquence du dépassement | F12: Réf.
A13: Trésorier (seul) | B13: 20 000 MRU | C13: Trimestriel | D13: 16 000 MRU | E13: Accord Président CG requis même si op. < 5 000 MRU | F13: Art. 47 bis §1
A14: Président CG (seul) | B14: 100 000 MRU | C14: Trimestriel | D14: 80 000 MRU | E14: Décision formelle du CG en réunion obligatoire | F14: Art. 47 bis §2
A15: CG en réunion | B15: 200 000 MRU | C15: Semestriel | D15: 160 000 MRU | E15: Saisine obligatoire de l'AG même si op. < 200 000 MRU | F15: Art. 47 bis §3
A16: Opération fractionnée | B16: Montant total | C16: Immédiat | D16: — | E16: Requalifiée comme dépense unique — autorisation totale | F16: Art. 47 bis §4
A18: C. PROCÉDURES DE PAIEMENT (Art. 48 & 49)
A19: Mode de paiement | B19: Limite | C19: Justificatif requis | D19: Responsable
A20: Virement / Chèque / Mobile money | B20: Tout montant > 5 000 MRU | C20: Bon de commande validé obligatoire | D20: Trésorier + Président selon seuil
A21: Espèces | B21: ≤ 5 000 MRU max | C21: Reçu signé par le bénéficiaire | D21: Trésorier seul
A22: Petite caisse | B22: Plafond fixé par CG | C22: Arrêté hebdomadaire obligatoire | D22: Trésorier Adjoint — vérif. COSC
A24: ⚠ ALERTE : Tout dépassement de plafond non autorisé préalablement constitue une FAUTE GRAVE → procédure disciplinaire Art. 60

Sheet 2. Bon de Dépense
A1: YELLITAARÉ THIDÉ — BON DE DÉPENSE
A2: Document obligatoire pour toute dépense — Art. 47, 47 bis & 48 | Yellitaaré Thidé
A4: IDENTIFICATION DE LA DÉPENSE
B5: N° Bon | C5: Référence unique auto-générée
B6: Date | C6: JJ/MM/AAAA
B7: Demandeur | C7: Nom et fonction
B8: Objet de la dépense | C8: Description précise
A10: MONTANT ET AUTORISATION
B11: Montant (MRU) | C11: Saisir le montant exact
B12: Mode de paiement | C12: Virement / Chèque / Mobile money / Espèces
B13: Fournisseur / Bénéficiaire | C13: Nom complet
B14: Compte / Numéro | C14: RIB ou numéro mobile money
A16: NIVEAU D'AUTORISATION REQUIS (calculé automatiquement)
B17: Niveau d'autorisation : | E17: =IF(C11="","— Saisir le montant —",IF(C11<=5000,"Trésorier seul (≤ 5 000 MRU)",IF(C11<=50000,"Accord Président CG (5 001 – 50 000 MRU)",IF(C11<=200000,"Décision CG en réunion (50 001 – 200 000 MRU)","Vote AG obligatoire (> 200 000 MRU)")))) -> Vote AG obligatoire (> 200 000 MRU)
A19: SIGNATURES ET VALIDATIONS
B20: Demandeur | D20: Trésorier | F20: Président CG | H20: Visa COSC
B21: Nom : | D21: Nom : | F21: Nom : | H21: Nom :
B22: Signature : | D22: Signature : | F22: Signature : | H22: Signature :
B23: Date : | D23: Date : | F23: Date : | H23: Date :

Sheet 3. Registre Dépenses
A1: YELLITAARÉ THIDÉ — REGISTRE DES DÉPENSES
A2: Tenu par le Trésorier — Art. 47, 48, 52 | Consultable par le COSC à tout moment
A4: SUIVI DES PLAFONDS CUMULÉS — ANTI-FRACTIONNEMENT (Art. 47 bis)
A5: Acteur | B5: Plafond | C5: Période | D5: Dépenses engagées (MRU) | E5: Solde disponible (MRU) | F5: Alerte 80% | G5: Statut
A6: Trésorier seul | B6: 20000 | C6: Trimestriel | D6: 0 | E6: =B6-D6 -> 20000 | F6: =B6*0.8 -> 16000 | G6: =IF(D6>=B6,"🔴 DÉPASSÉ",IF(D6>=F6,"🟠 ALERTE 80%","🟢 OK")) -> 🟢 OK
A7: Président CG seul | B7: 100000 | C7: Trimestriel | D7: 0 | E7: =B7-D7 -> 100000 | F7: =B7*0.8 -> 80000 | G7: =IF(D7>=B7,"🔴 DÉPASSÉ",IF(D7>=F7,"🟠 ALERTE 80%","🟢 OK")) -> 🟢 OK
A8: CG en réunion | B8: 200000 | C8: Semestriel | D8: 0 | E8: =B8-D8 -> 200000 | F8: =B8*0.8 -> 160000 | G8: =IF(D8>=B8,"🔴 DÉPASSÉ",IF(D8>=F8,"🟠 ALERTE 80%","🟢 OK")) -> 🟢 OK
A9: REGISTRE DÉTAILLÉ DES DÉPENSES
A10: N° | B10: Date | C10: Objet de la dépense | D10: Bénéficiaire | E10: Montant (MRU) | F10: Mode paiement | G10: N° Bon | H10: Niveau autorisation | I10: Trésorier ✓ | J10: Président ✓ | K10: COSC ✓
A11: =IF(C11<>"",ROW()-10,"") | H11: =IF(E11="","",IF(E11<=5000,"Trésorier seul",IF(E11<=50000,"Président CG",IF(E11<=200000,"CG en réunion","Vote AG"))))
A12: =IF(C12<>"",ROW()-10,"") | H12: =IF(E12="","",IF(E12<=5000,"Trésorier seul",IF(E12<=50000,"Président CG",IF(E12<=200000,"CG en réunion","Vote AG"))))
A13: =IF(C13<>"",ROW()-10,"") | H13: =IF(E13="","",IF(E13<=5000,"Trésorier seul",IF(E13<=50000,"Président CG",IF(E13<=200000,"CG en réunion","Vote AG"))))
A14: =IF(C14<>"",ROW()-10,"") | H14: =IF(E14="","",IF(E14<=5000,"Trésorier seul",IF(E14<=50000,"Président CG",IF(E14<=200000,"CG en réunion","Vote AG"))))
A15: =IF(C15<>"",ROW()-10,"") | H15: =IF(E15="","",IF(E15<=5000,"Trésorier seul",IF(E15<=50000,"Président CG",IF(E15<=200000,"CG en réunion","Vote AG"))))
A16: =IF(C16<>"",ROW()-10,"") | H16: =IF(E16="","",IF(E16<=5000,"Trésorier seul",IF(E16<=50000,"Président CG",IF(E16<=200000,"CG en réunion","Vote AG"))))
A17: =IF(C17<>"",ROW()-10,"") | H17: =IF(E17="","",IF(E17<=5000,"Trésorier seul",IF(E17<=50000,"Président CG",IF(E17<=200000,"CG en réunion","Vote AG"))))
A18: =IF(C18<>"",ROW()-10,"") | H18: =IF(E18="","",IF(E18<=5000,"Trésorier seul",IF(E18<=50000,"Président CG",IF(E18<=200000,"CG en réunion","Vote AG"))))
A19: =IF(C19<>"",ROW()-10,"") | H19: =IF(E19="","",IF(E19<=5000,"Trésorier seul",IF(E19<=50000,"Président CG",IF(E19<=200000,"CG en réunion","Vote AG"))))
A20: =IF(C20<>"",ROW()-10,"") | H20: =IF(E20="","",IF(E20<=5000,"Trésorier seul",IF(E20<=50000,"Président CG",IF(E20<=200000,"CG en réunion","Vote AG"))))
A21: =IF(C21<>"",ROW()-10,"") | H21: =IF(E21="","",IF(E21<=5000,"Trésorier seul",IF(E21<=50000,"Président CG",IF(E21<=200000,"CG en réunion","Vote AG"))))
A22: =IF(C22<>"",ROW()-10,"") | H22: =IF(E22="","",IF(E22<=5000,"Trésorier seul",IF(E22<=50000,"Président CG",IF(E22<=200000,"CG en réunion","Vote AG"))))
... A30: =IF(C30<>"",ROW()-10,"") | H30: =IF(E30="","",IF(E30<=5000,"Trésorier seul",IF(E30<=50000,"Président CG",IF(E30<=200000,"CG en réunion","Vote AG"))))
D31: TOTAL DÉPENSES : | E31: =SUM(E11:E30) -> 0

Sheet 4. Registre Cotisations
A1: YELLITAARÉ THIDÉ — REGISTRE DES COTISATIONS
A2: Tenu par le Trésorier Adjoint — Art. 50 | Un reçu numéroté remis à chaque cotisant | Consultable par le COSC
A4: SYNTHÈSE DES COTISATIONS PAR SECTION
A5: Section | C5: Membres inscrits | E5: Cotisants à jour | G5: Taux recouvrement | I5: Total collecté (MRU)
A6: Section 1 — Village | C6: 0 | E6: 0 | G6: =IF(B6=0,0,C6/B6) -> 0 | I6: 0
A7: Section 2 — Nationaux | C7: 0 | E7: 0 | G7: =IF(B7=0,0,C7/B7) -> 0 | I7: 0
A8: Section 3 — Diaspora | C8: 0 | E8: 0 | G8: =IF(B8=0,0,C8/B8) -> 0 | I8: 0
A10: REGISTRE NOMINATIF DES COTISATIONS
A11: N° | B11: Nom et Prénom | C11: Section | D11: Catégorie | E11: Montant (MRU) | F11: N° Reçu | G11: Date versement | H11: Mode paiement | I11: Statut | J11: Observations
A12: =IF(B12<>"",ROW()-11,"")
A13: =IF(B13<>"",ROW()-11,"")
A14: =IF(B14<>"",ROW()-11,"")
A15: =IF(B15<>"",ROW()-11,"")
A16: =IF(B16<>"",ROW()-11,"")
A17: =IF(B17<>"",ROW()-11,"")
A18: =IF(B18<>"",ROW()-11,"")
A19: =IF(B19<>"",ROW()-11,"")
A20: =IF(B20<>"",ROW()-11,"")
A21: =IF(B21<>"",ROW()-11,"")
A22: =IF(B22<>"",ROW()-11,"")
A23: =IF(B23<>"",ROW()-11,"")
... A41: =IF(B41<>"",ROW()-11,"")
D42: TOTAL COLLECTÉ : | E42: =SUM(E12:E41) -> 0

Sheet 5. Tableau de Bord
A1: YELLITAARÉ THIDÉ — TABLEAU DE BORD FINANCIER
A2: Vue synthétique — Cotisations · Dépenses · Plafonds · Alertes | Art. 47, 50, 52
B4: 💰 Total Cotisations | C4: 📤 Total Dépenses | D4: 🏦 Solde Disponible | E4: ⚠ Alertes Actives
B5: ='4. Registre Cotisations'!E42 -> 0 | C5: ='3. Registre Dépenses'!E31 -> 0 | D5: ='4. Registre Cotisations'!E42-'3. Registre Dépenses'!E31 -> 0 | E5: =COUNTIF('3. Registre Dépenses'!G6:G8,"🔴 DÉPASSÉ")+COUNTIF('3. Registre Dépenses'!G6:G8,"🟠 ALERTE 80%") -> 0
A8: SUIVI DES PLAFONDS EN TEMPS RÉEL
B9: Acteur | C9: Plafond | D9: Période | E9: Utilisé | F9: Disponible | G9: Statut
B10: Trésorier seul | C10: 20000 | D10: Mensuel | E10: ='3. Registre Dépenses'!D6 -> 0 | F10: ='3. Registre Dépenses'!E6 -> 20000 | G10: ='3. Registre Dépenses'!G6 -> 🟢 OK
B11: Président CG seul | C11: 100000 | D11: Trimestriel | E11: ='3. Registre Dépenses'!D7 -> 0 | F11: ='3. Registre Dépenses'!E7 -> 100000 | G11: ='3. Registre Dépenses'!G7 -> 🟢 OK
B12: CG en réunion | C12: 200000 | D12: Semestriel | E12: ='3. Registre Dépenses'!D8 -> 0 | F12: ='3. Registre Dépenses'!E8 -> 200000 | G12: ='3. Registre Dépenses'!G8 -> 🟢 OK
A14: RAPPEL DES RÈGLES CLÉS (Art. 47 bis)
B15: ▸ Signaler au Président CG et au COSC dès que le cumul atteint 80 % du plafond applicable
B16: ▸ Toute opération fractionnée sur un même objet ou fournisseur = requalifiée en dépense unique
B17: ▸ Tout dépassement non autorisé = faute grave → procédure disciplinaire Art. 60
B18: ▸ Pas de compte personnel pour les fonds communautaires (Art. 46)
B19: ▸ Tout paiement supérieur à 5 000 MRU : virement / chèque / mobile money uniquement
